<?xml version="1.0" ?>
<!-- ===================================================================================  -->
<!-- |    This document was autogenerated by xacro from /home/florent/devel/hpp/install/share/agimus_demos/franka/manipulation/urdf/demo.urdf.xacro  | -->
<!-- |    EDITING THIS FILE BY HAND IS NOT RECOMMENDED                                  | -->
<!-- ===================================================================================  -->
<robot name="pandas">
  <link name="support_link">
    <inertial>
       <mass value="200"/>
      <origin xyz="0 0 0.45"/>
      <inertia ixx="  50" ixy="0" ixz="0" iyy="50" iyz="0" izz="50"/>
    </inertial>
     <visual>
      <origin xyz="0 0 0.38"/>
      <geometry>
        <box size="  1.703 0.803 0.76"/>
      </geometry>
    </visual>
    <collision>
      <origin  xyz="0 0 0.38"/>
      <geometry>
        <box size="1.703 0.803 0.76"/>
       </geometry>
    </collision>
    <!--visual>
          <origin xyz="  -0.61 0.2215 0.77"/>
          <geometry>
	    <box size="0.363 0.252 0.02"  />
          </geometry>
        </visual>
        <collision>
          <origin  xyz="-0.61 0.2215 0.77"/>
          <geometry>
	    <box size="0.363 0.252  0.02"/>
          </geometry>
        </collision-->
    <visual>
      <origin  xyz="0.6385 -0.1655 0.77"/>
      <geometry>
        <box size="0.3 0.3 0.02"  />
      </geometry>
    </visual>
    <collision>
      <origin xyz="0.6385  -0.1655 0.77"/>
      <geometry>
        <box size="0.3 0.3 0.02"/>
       </geometry>
    </collision>
  </link>
  <link name="wall_link">
    <inertial>
       <mass value="200"/>
      <origin xyz="0 0 1."/>
      <inertia ixx="  50" ixy="0" ixz="0" iyy="50" iyz="0" izz="50"/>
    </inertial>
     <visual>
      <origin xyz="0 0 1.0"/>
      <geometry>
        <box size="  3.0 0.1 2.0"/>
      </geometry>
    </visual>
    <collision>
      <origin  xyz="0 0 1.0"/>
      <geometry>
        <box size="3.0 0.1 2.0"/>
       </geometry>
    </collision>
  </link>
  <!-- Wrap panda1 robot into a box  shaped obstacle -->
  <link name="panda1_box">
    <inertial>
      <mass  value="100"/>
      <origin xyz="0 0 0"/>
      <inertia ixx="25" ixy="  0" ixz="0" iyy="25" iyz="0" izz="25"/>
    </inertial>
    <collision>
       <origin xyz="0 0 0"/>
      <geometry>
        <box size="0.44 0.803  0.80"/>
      </geometry>
    </collision>
    <visual>
      <origin xyz="  0 0 0"/>
      <geometry>
        <box size="0.44 0.803 0.80"/>
      </geometry>
       <material name="lightGrey">
        <color rgba="0.9 0.9 0.9 0.5"/>
       </material>
    </visual>
  </link>
  <!-- Gazebo requires a joint to  a link called "world" for statically mounted robots -->
  <link name="world"  />
  <joint name="world_joint" type="fixed">
    <origin rpy="0 0 0" xyz="  0 0 0"/>
    <parent link="world"/>
    <child link="support_link"/>
  </joint>
   <joint name="support_joint" type="fixed">
    <origin rpy="0 0 3.141592653589793"  xyz="0.563 -0.1655 .78"/>
    <parent link="support_link"/>
    <child link="  panda2_link0"/>
  </joint>
  <joint name="wall_joint" type="fixed">
     <origin xyz="0 1.07 0"/>
    <parent link="world"/>
    <child link="wall_link"  />
  </joint>
  <joint name="panda1_box_joint" type="fixed">
    <origin  xyz="-0.6315 0 1.17"/>
    <parent link="world"/>
    <child link="panda1_box"  />
  </joint>
  <!-- sub-link defining detailed meshes for collision with environment  -->
  <link name="panda2_link0">
    <visual>
      <geometry>
        <mesh  filename="package://franka_description/meshes/visual/link0.dae"/>
      </geometry>
     </visual>
    <collision>
      <geometry>
        <mesh filename="package://franka_description/meshes/collision/link0.stl"  />
      </geometry>
    </collision>
    <inertial>
      <origin rpy="0 0  0" xyz="-0.041018 -0.00014 0.049974"/>
      <mass value="0.629769"/>
       <inertia ixx="0.00315" ixy="8.2904e-07" ixz="0.00015" iyy="0.00388"  iyz="8.2299e-06" izz="0.004285"/>
    </inertial>
  </link>
  <!-- sub-link  defining coarse geometries of real robot's internal self-collision -->
  <link  name="panda2_link0_sc">
  </link>
  <!-- fixed joint between both sub-links  -->
  <joint name="panda2_link0_sc_joint" type="fixed">
    <origin rpy="  0 0 0"/>
    <parent link="panda2_link0"/>
    <child link="panda2_link0_sc"  />
  </joint>
  <!-- sub-link defining detailed meshes for collision with environment  -->
  <link name="panda2_link1">
    <visual>
      <geometry>
        <mesh  filename="package://franka_description/meshes/visual/link1.dae"/>
      </geometry>
     </visual>
    <collision>
      <geometry>
        <mesh filename="package://franka_description/meshes/collision/link1.stl"  />
      </geometry>
    </collision>
    <inertial>
      <origin rpy="0 0  0" xyz="0.003875 0.002081 -0.04762"/>
      <mass value="4.970684"/>
       <inertia ixx="0.70337" ixy="-0.000139" ixz="0.006772" iyy="0.70661"  iyz="0.019169" izz="0.009117"/>
    </inertial>
  </link>
  <!-- sub-link  defining coarse geometries of real robot's internal self-collision -->
  <link  name="panda2_link1_sc">
  </link>
  <!-- fixed joint between both sub-links  -->
  <joint name="panda2_link1_sc_joint" type="fixed">
    <origin rpy="  0 0 0"/>
    <parent link="panda2_link1"/>
    <child link="panda2_link1_sc"  />
  </joint>
  <joint name="panda2_joint1" type="revolute">
    <origin  rpy="0 0 0" xyz="0 0 0.333"/>
    <parent link="panda2_link0"/>
    <child  link="panda2_link1"/>
    <axis xyz="0 0 1"/>
    <limit effort="87.0"  lower="-2.8973" upper="2.8973" velocity="2.175"/>
    <safety_controller  k_position="100.0" k_velocity="40.0" soft_lower_limit="-2.8973" soft_upper_limit="  2.8973"/>
    <dynamics D="1" K="7000" damping="0.003" friction="0.0"  mu_coulomb="0" mu_viscous="16"/>
  </joint>
  <!-- sub-link defining detailed  meshes for collision with environment -->
  <link name="panda2_link2">
     <visual>
      <geometry>
        <mesh filename="package://franka_description/meshes/visual/link2.dae"  />
      </geometry>
    </visual>
    <collision>
      <geometry>
         <mesh filename="package://franka_description/meshes/collision/link2.stl"/>
       </geometry>
    </collision>
    <inertial>
      <origin rpy="0 0 0"  xyz="-0.003141 -0.02872  0.003495"/>
      <mass value="0.646926"/>
       <inertia ixx="0.007962" ixy="-0.003925" ixz="0.010254" iyy="0.02811"  iyz="0.000704" izz="0.025995"/>
    </inertial>
  </link>
  <!-- sub-link  defining coarse geometries of real robot's internal self-collision -->
  <link  name="panda2_link2_sc">
  </link>
  <!-- fixed joint between both sub-links  -->
  <joint name="panda2_link2_sc_joint" type="fixed">
    <origin rpy="  0 0 0"/>
    <parent link="panda2_link2"/>
    <child link="panda2_link2_sc"  />
  </joint>
  <joint name="panda2_joint2" type="revolute">
    <origin  rpy="-1.5707963267948966 0 0" xyz="0 0 0"/>
    <parent link="panda2_link1"  />
    <child link="panda2_link2"/>
    <axis xyz="0 0 1"/>
    <limit effort="  87.0" lower="-1.7628" upper="1.7628" velocity="2.175"/>
    <safety_controller  k_position="100.0" k_velocity="40.0" soft_lower_limit="-1.7628" soft_upper_limit="  1.7628"/>
    <dynamics D="1" K="7000" damping="0.003" friction="0.0"  mu_coulomb="0" mu_viscous="16"/>
  </joint>
  <!-- sub-link defining detailed  meshes for collision with environment -->
  <link name="panda2_link3">
     <visual>
      <geometry>
        <mesh filename="package://franka_description/meshes/visual/link3.dae"  />
      </geometry>
    </visual>
    <collision>
      <geometry>
         <mesh filename="package://franka_description/meshes/collision/link3.stl"/>
       </geometry>
    </collision>
    <inertial>
      <origin rpy="0 0 0"  xyz="2.7518e-02 3.9252e-02 -6.6502e-02"/>
      <mass value="3.228604"/>
       <inertia ixx="0.037242" ixy="-0.004761" ixz="-0.011396" iyy="0.036155"  iyz="-0.012805" izz="0.01083"/>
    </inertial>
  </link>
  <!-- sub-link  defining coarse geometries of real robot's internal self-collision -->
  <link  name="panda2_link3_sc">
  </link>
  <!-- fixed joint between both sub-links  -->
  <joint name="panda2_link3_sc_joint" type="fixed">
    <origin rpy="  0 0 0"/>
    <parent link="panda2_link3"/>
    <child link="panda2_link3_sc"  />
  </joint>
  <joint name="panda2_joint3" type="revolute">
    <origin  rpy="1.5707963267948966 0 0" xyz="0 -0.316 0"/>
    <parent link="panda2_link2"  />
    <child link="panda2_link3"/>
    <axis xyz="0 0 1"/>
    <limit effort="  87.0" lower="-2.8973" upper="2.8973" velocity="2.175"/>
    <safety_controller  k_position="100.0" k_velocity="40.0" soft_lower_limit="-2.8973" soft_upper_limit="  2.8973"/>
    <dynamics D="1" K="7000" damping="0.003" friction="0.0"  mu_coulomb="0" mu_viscous="16"/>
  </joint>
  <!-- sub-link defining detailed  meshes for collision with environment -->
  <link name="panda2_link4">
     <visual>
      <geometry>
        <mesh filename="package://franka_description/meshes/visual/link4.dae"  />
      </geometry>
    </visual>
    <collision>
      <geometry>
         <mesh filename="package://franka_description/meshes/collision/link4.stl"/>
       </geometry>
    </collision>
    <inertial>
      <origin rpy="0 0 0"  xyz="-5.317e-02 1.04419e-01 2.7454e-02"/>
      <mass value="3.587895"/>
       <inertia ixx="0.025853" ixy="0.007796" ixz="-0.001332" iyy="0.019552"  iyz="0.008641" izz="0.028323"/>
    </inertial>
  </link>
  <!-- sub-link  defining coarse geometries of real robot's internal self-collision -->
  <link  name="panda2_link4_sc">
  </link>
  <!-- fixed joint between both sub-links  -->
  <joint name="panda2_link4_sc_joint" type="fixed">
    <origin rpy="  0 0 0"/>
    <parent link="panda2_link4"/>
    <child link="panda2_link4_sc"  />
  </joint>
  <joint name="panda2_joint4" type="revolute">
    <origin  rpy="1.5707963267948966 0 0" xyz="0.0825 0 0"/>
    <parent link="panda2_link3"  />
    <child link="panda2_link4"/>
    <axis xyz="0 0 1"/>
    <limit effort="  87.0" lower="-3.0718" upper="-0.0698" velocity="2.175"/>
    <safety_controller  k_position="100.0" k_velocity="40.0" soft_lower_limit="-3.0718" soft_upper_limit="  -0.0698"/>
    <dynamics D="1" K="7000" damping="0.003" friction="0.0"  mu_coulomb="0" mu_viscous="16"/>
  </joint>
  <!-- sub-link defining detailed  meshes for collision with environment -->
  <link name="panda2_link5">
     <visual>
      <geometry>
        <mesh filename="package://franka_description/meshes/visual/link5.dae"  />
      </geometry>
    </visual>
    <collision>
      <geometry>
         <mesh filename="package://franka_description/meshes/collision/link5.stl"/>
       </geometry>
    </collision>
    <inertial>
      <origin rpy="0 0 0"  xyz="-1.1953e-02 4.1065e-02 -3.8437e-02"/>
      <mass value="1.225946"/>
       <inertia ixx="0.035549" ixy="-0.002117" ixz="-0.004037" iyy="0.029474"  iyz="0.000229" izz="0.008627"/>
    </inertial>
  </link>
  <!-- sub-link  defining coarse geometries of real robot's internal self-collision -->
  <link  name="panda2_link5_sc">
  </link>
  <!-- fixed joint between both sub-links  -->
  <joint name="panda2_link5_sc_joint" type="fixed">
    <origin rpy="  0 0 0"/>
    <parent link="panda2_link5"/>
    <child link="panda2_link5_sc"  />
  </joint>
  <joint name="panda2_joint5" type="revolute">
    <origin  rpy="-1.5707963267948966 0 0" xyz="-0.0825 0.384 0"/>
    <parent link="  panda2_link4"/>
    <child link="panda2_link5"/>
    <axis xyz="0 0 1"/>
     <limit effort="12.0" lower="-2.8973" upper="2.8973" velocity="2.61"  />
    <safety_controller k_position="100.0" k_velocity="40.0" soft_lower_limit="  -2.8973" soft_upper_limit="2.8973"/>
    <dynamics D="1" K="7000" damping="  0.003" friction="0.0" mu_coulomb="0" mu_viscous="16"/>
  </joint>
  <!--  sub-link defining detailed meshes for collision with environment -->
  <link  name="panda2_link6">
    <visual>
      <geometry>
        <mesh filename="  package://franka_description/meshes/visual/link6.dae"/>
      </geometry>
     </visual>
    <collision>
      <geometry>
        <mesh filename="package://franka_description/meshes/collision/link6.stl"  />
      </geometry>
    </collision>
    <inertial>
      <origin rpy="0 0  0" xyz="6.0149e-02 -1.4117e-02 -1.0517e-02"/>
      <mass value="1.666555"  />
      <inertia ixx="0.001964" ixy="0.000109" ixz="-0.001158" iyy="0.004354"  iyz="0.000341" izz="0.005433"/>
    </inertial>
  </link>
  <!-- sub-link  defining coarse geometries of real robot's internal self-collision -->
  <link  name="panda2_link6_sc">
  </link>
  <!-- fixed joint between both sub-links  -->
  <joint name="panda2_link6_sc_joint" type="fixed">
    <origin rpy="  0 0 0"/>
    <parent link="panda2_link6"/>
    <child link="panda2_link6_sc"  />
  </joint>
  <joint name="panda2_joint6" type="revolute">
    <origin  rpy="1.5707963267948966 0 0" xyz="0 0 0"/>
    <parent link="panda2_link5"  />
    <child link="panda2_link6"/>
    <axis xyz="0 0 1"/>
    <limit effort="  12.0" lower="-0.0175" upper="3.7525" velocity="2.61"/>
    <safety_controller  k_position="100.0" k_velocity="40.0" soft_lower_limit="-0.0175" soft_upper_limit="  3.7525"/>
    <dynamics D="1" K="7000" damping="0.003" friction="0.0"  mu_coulomb="0" mu_viscous="16"/>
  </joint>
  <!-- sub-link defining detailed  meshes for collision with environment -->
  <link name="panda2_link7">
     <visual>
      <geometry>
        <mesh filename="package://franka_description/meshes/visual/link7.dae"  />
      </geometry>
    </visual>
    <collision>
      <geometry>
         <mesh filename="package://franka_description/meshes/collision/link7.stl"/>
       </geometry>
    </collision>
    <inertial>
      <origin rpy="0 0 0"  xyz="1.0517e-02 -4.252e-03 6.1597e-02"/>
      <mass value="0.735522"/>
       <inertia ixx="0.012516" ixy="-0.000428" ixz="-0.001196" iyy="0.010027"  iyz="-0.000741" izz="0.004815"/>
    </inertial>
  </link>
  <!-- sub-link  defining coarse geometries of real robot's internal self-collision -->
  <link  name="panda2_link7_sc">
  </link>
  <!-- fixed joint between both sub-links  -->
  <joint name="panda2_link7_sc_joint" type="fixed">
    <origin rpy="  0 0 0.7853981633974483"/>
    <parent link="panda2_link7"/>
    <child link="  panda2_link7_sc"/>
  </joint>
  <joint name="panda2_joint7" type="revolute"  >
    <origin rpy="1.5707963267948966 0 0" xyz="0.088 0 0"/>
    <parent link="  panda2_link6"/>
    <child link="panda2_link7"/>
    <axis xyz="0 0 1"/>
     <limit effort="12.0" lower="-2.8973" upper="2.8973" velocity="2.61"  />
    <safety_controller k_position="100.0" k_velocity="40.0" soft_lower_limit="  -2.8973" soft_upper_limit="2.8973"/>
    <dynamics D="1" K="7000" damping="  0.003" friction="0.0" mu_coulomb="0" mu_viscous="16"/>
  </joint>
  <link  name="panda2_link8"/>
  <joint name="panda2_joint8" type="fixed">
     <origin rpy="0 0 0" xyz="0 0 0.107"/>
    <parent link="panda2_link7"/>
     <child link="panda2_link8"/>
  </joint>
  <joint name="panda2_hand_joint"  type="fixed">
    <parent link="panda2_link8"/>
    <child link="panda2_hand"  />
    <origin rpy="0 0 -0.7853981633974483" xyz="0 0 0"/>
  </joint>
  <!--  sub-link defining detailed meshes for collision with environment -->
  <link  name="panda2_hand">
    <visual>
      <geometry>
        <mesh filename="  package://franka_description/meshes/visual/hand.dae"/>
      </geometry>
     </visual>
    <collision>
      <geometry>
        <mesh filename="package://franka_description/meshes/collision/hand.stl"  />
      </geometry>
    </collision>
    <inertial>
      <origin rpy="0 0  0" xyz="-0.01 0 0.03"/>
      <mass value="0.73"/>
      <inertia ixx="  0.001" ixy="0" ixz="0" iyy="0.0025" iyz="0" izz="0.0017"/>
    </inertial>
   </link>
  <!-- sub-link defining coarse geometries of real robot's internal  self-collision -->
  <link name="panda2_hand_sc">
  </link>
  <!-- fixed  joint between both sub-links -->
  <joint name="panda2_hand_sc_joint" type="  fixed">
    <origin rpy="0 0 0"/>
    <parent link="panda2_hand"/>
    <child  link="panda2_hand_sc"/>
  </joint>
  <!-- Define the hand_tcp frame -->
   <link name="panda2_hand_tcp"/>
  <joint name="panda2_hand_tcp_joint" type="  fixed">
    <origin rpy="0 0 0" xyz="0 0 0.1034"/>
    <parent link="panda2_hand"  />
    <child link="panda2_hand_tcp"/>
  </joint>
  <link name="panda2_leftfinger"  >
    <visual>
      <geometry>
        <mesh filename="package://franka_description/meshes/visual/finger.dae"  />
      </geometry>
    </visual>
    <!-- screw mount -->
    <collision>
       <origin rpy="0 0 0" xyz="0 18.5e-3 11e-3"/>
      <geometry>
         <box size="22e-3 15e-3 20e-3"/>
      </geometry>
    </collision>
     <!-- cartriage sledge -->
    <collision>
      <origin rpy="0 0 0" xyz="  0 6.8e-3 2.2e-3"/>
      <geometry>
        <box size="22e-3 8.8e-3 3.8e-3"  />
      </geometry>
    </collision>
    <!-- diagonal finger -->
    <collision>
       <origin rpy="0.5235987755982988 0 0" xyz="0 15.9e-3 28.35e-3"/>
       <geometry>
        <box size="17.5e-3 7e-3 23.5e-3"/>
      </geometry>
     </collision>
    <!-- rubber tip with which to grasp -->
    <collision>
       <origin rpy="0 0 0" xyz="0 7.58e-3 45.25e-3"/>
      <geometry>
         <box size="17.5e-3 15.2e-3 18.5e-3"/>
      </geometry>
    </collision>
     <inertial>
      <origin rpy="0 0 0" xyz="0 0 0"/>
      <mass value="  0.015"/>
      <inertia ixx="2.3749999999999997e-06" ixy="0" ixz="0" iyy="  2.3749999999999997e-06" iyz="0" izz="7.5e-07"/>
    </inertial>
  </link>
   <link name="panda2_rightfinger">
    <visual>
      <origin rpy="0 0 3.141592653589793"  xyz="0 0 0"/>
      <geometry>
        <mesh filename="package://franka_description/meshes/visual/finger.dae"  />
      </geometry>
    </visual>
    <!-- screw mount -->
    <collision>
       <origin rpy="0 0 0" xyz="0 -18.5e-3 11e-3"/>
      <geometry>
         <box size="22e-3 15e-3 20e-3"/>
      </geometry>
    </collision>
     <!-- cartriage sledge -->
    <collision>
      <origin rpy="0 0 0" xyz="  0 -6.8e-3 2.2e-3"/>
      <geometry>
        <box size="22e-3 8.8e-3 3.8e-3"  />
      </geometry>
    </collision>
    <!-- diagonal finger -->
    <collision>
       <origin rpy="-0.5235987755982988 0 0" xyz="0 -15.9e-3 28.35e-3"/>
       <geometry>
        <box size="17.5e-3 7e-3 23.5e-3"/>
      </geometry>
     </collision>
    <!-- rubber tip with which to grasp -->
    <collision>
       <origin rpy="0 0 0" xyz="0 -7.58e-3 45.25e-3"/>
      <geometry>
         <box size="17.5e-3 15.2e-3 18.5e-3"/>
      </geometry>
    </collision>
     <inertial>
      <origin rpy="0 0 0" xyz="0 0 0"/>
      <mass value="  0.015"/>
      <inertia ixx="2.3749999999999997e-06" ixy="0" ixz="0" iyy="  2.3749999999999997e-06" iyz="0" izz="7.5e-07"/>
    </inertial>
  </link>
   <joint name="panda2_finger_joint1" type="prismatic">
    <parent link="  panda2_hand"/>
    <child link="panda2_leftfinger"/>
    <origin rpy="0 0  0" xyz="0 0 0.0584"/>
    <axis xyz="0 1 0"/>
    <limit effort="100"  lower="0.0" upper="0.04" velocity="0.2"/>
    <dynamics damping="0.3"  />
  </joint>
  <joint name="panda2_finger_joint2" type="prismatic">
     <parent link="panda2_hand"/>
    <child link="panda2_rightfinger"/>
     <origin rpy="0 0 0" xyz="0 0 0.0584"/>
    <axis xyz="0 -1 0"/>
    <limit  effort="100" lower="0.0" upper="0.04" velocity="0.2"/>
    <mimic joint="  panda2_finger_joint1"/>
    <dynamics damping="0.3"/>
  </joint>
  <link name="  panda2_ref_camera_link"/>
  <joint name="panda2_ref_camera_joint" type="fixed"  >
    <parent link="panda2_hand"/>
    <child link="panda2_ref_camera_link"  />
    <origin rpy="3.14159265                    -1.57079633                     0.0" xyz="0.02                    0.0                    0.045"/>
  </joint>
   <material name="aluminum">
    <color rgba="0.5 0.5 0.5 1"/>
  </material>
   <material name="plastic">
    <color rgba="0.1 0.1 0.1 1"/>
  </material>
   <!-- camera body, with origin at bottom screw mount -->
  <joint name="camera_joint"  type="fixed">
    <origin rpy="0 0 0" xyz="0 0 0"/>
    <parent link="  panda2_ref_camera_link"/>
    <child link="camera_bottom_screw_frame"/>
  </joint>
   <link name="camera_bottom_screw_frame"/>
  <joint name="camera_link_joint"  type="fixed">
    <origin rpy="0 0 0" xyz="0.010600000000000002 0.0175 0.0125"  />
    <parent link="camera_bottom_screw_frame"/>
    <child link="camera_link"  />
  </joint>
  <link name="camera_link">
    <visual>
      <!-- the mesh  origin is at front plate in between the two infrared camera axes -->
      <origin  rpy="1.5707963267948966 0 1.5707963267948966" xyz="0.0043 -0.0175 0"/>
       <geometry>
        <mesh filename="package://realsense2_description/meshes/d435.dae"  />
      </geometry>
    </visual>
    <collision>
      <origin rpy="0 0 0"  xyz="0 -0.0175 0"/>
      <geometry>
        <box size="0.02505 0.09 0.025"  />
      </geometry>
    </collision>
    <inertial>
      <!-- The following  are not reliable values, and should not be used for modeling -->
      <mass  value="0.072"/>
      <origin xyz="0 0 0"/>
      <inertia ixx="0.003881243"  ixy="0.0" ixz="0.0" iyy="0.000498940" iyz="0.0" izz="0.003879257"/>
     </inertial>
  </link>
  <!-- camera depth joints and links -->
  <joint  name="camera_depth_joint" type="fixed">
    <origin rpy="0 0 0" xyz="  0 0 0"/>
    <parent link="camera_link"/>
    <child link="camera_depth_frame"  />
  </joint>
  <link name="camera_depth_frame"/>
  <joint name="camera_depth_optical_joint"  type="fixed">
    <origin rpy="-1.5707963267948966 0 -1.5707963267948966"  xyz="0 0 0"/>
    <parent link="camera_depth_frame"/>
    <child link="  camera_depth_optical_frame"/>
  </joint>
  <link name="camera_depth_optical_frame"  />
  <!-- camera left IR joints and links -->
  <joint name="camera_infra1_joint"  type="fixed">
    <origin rpy="0 0 0" xyz="0 0.0 0"/>
    <parent link="  camera_link"/>
    <child link="camera_infra1_frame"/>
  </joint>
  <link  name="camera_infra1_frame"/>
  <joint name="camera_infra1_optical_joint"  type="fixed">
    <origin rpy="-1.5707963267948966 0 -1.5707963267948966"  xyz="0 0 0"/>
    <parent link="camera_infra1_frame"/>
    <child link="  camera_infra1_optical_frame"/>
  </joint>
  <link name="camera_infra1_optical_frame"  />
  <!-- camera right IR joints and links -->
  <joint name="camera_infra2_joint"  type="fixed">
    <origin rpy="0 0 0" xyz="0 -0.05 0"/>
    <parent link="  camera_link"/>
    <child link="camera_infra2_frame"/>
  </joint>
  <link  name="camera_infra2_frame"/>
  <joint name="camera_infra2_optical_joint"  type="fixed">
    <origin rpy="-1.5707963267948966 0 -1.5707963267948966"  xyz="0 0 0"/>
    <parent link="camera_infra2_frame"/>
    <child link="  camera_infra2_optical_frame"/>
  </joint>
  <link name="camera_infra2_optical_frame"  />
  <!-- camera color joints and links -->
  <joint name="camera_color_joint"  type="fixed">
    <origin rpy="0 0 0" xyz="0 0.015 0"/>
    <parent link="  camera_link"/>
    <child link="camera_color_frame"/>
  </joint>
  <link name="  camera_color_frame"/>
  <joint name="camera_color_optical_joint" type="fixed"  >
    <origin rpy="-1.5707963267948966 0 -1.5707963267948966" xyz="0 0 0"/>
     <parent link="camera_color_frame"/>
    <child link="camera_color_optical_frame"  />
  </joint>
  <link name="camera_color_optical_frame"/>
  <!-- camera support  -->
  <link name="panda2_camera_support_link">
    <inertial>
      <mass  value="0.010"/>
      <origin xyz="0 0 0"/>
      <inertia ixx="0.001"  ixy="0" ixz="0" iyy="0.001" iyz="0" izz="0.001"/>
    </inertial>
     <visual>
      <origin rpy="3.141592653589793 0 -1.5707963267948966" xyz="  0.022 -0.102 0.036"/>
      <geometry>
        <mesh filename="package://agimus_demos/franka/manipulation/meshes/camera-support.stl"  scale="0.001 0.001 0.001"/>
      </geometry>
    </visual>
    <collision>
       <origin rpy="3.141592653589793 0 -1.5707963267948966" xyz="0.022 -0.102  0.036"/>
      <geometry>
        <mesh filename="package://agimus_demos/franka/manipulation/meshes/camera-support.stl"  scale="0.001 0.001 0.001"/>
      </geometry>
    </collision>
  </link>
   <joint name="panda2_camera_support_joint" type="fixed">
    <parent link="  panda2_hand"/>
    <child link="panda2_camera_support_link"/>
    <origin rpy="  0 0 0" xyz="0 0 0"/>
  </joint>
  <gazebo reference="panda2_ref_camera_link"  >
    <self_collide>0</self_collide>
    <enable_wind>0</enable_wind>
    <kinematic>0</kinematic>
     <gravity>1</gravity>
    <!--<mu>1</mu>-->
    <mu2>1</mu2>
    <fdir1>0  0 0</fdir1>
    <!--<slip1>0</slip1>
      <slip2>0</slip2>-->
    <kp>1e+13</kp>
     <kd>1</kd>
    <!--<max_vel>0.01</max_vel>
      <min_depth>0</min_depth>-->
     <sensor name="d435color" type="camera">
      <camera name="d435">
         <horizontal_fov>1.2112585008840648</horizontal_fov>
        <image>
           <width>1920</width>
          <height>1080</height>
          <format>RGB_INT8</format>
         </image>
        <clip>
          <near>0.1</near>
          <far>100</far>
         </clip>
        <noise>
          <type>gaussian</type>
          <mean>0.0</mean>
           <stddev>0.007</stddev>
        </noise>
      </camera>
      <always_on>1</always_on>
       <update_rate>30</update_rate>
      <visualize>1</visualize>
    </sensor>
     <sensor name="d435ired1" type="camera">
      <camera name="d435">
         <horizontal_fov>1.4870205226991688</horizontal_fov>
        <image>
           <width>1280</width>
          <height>720</height>
          <format>L_INT8</format>
         </image>
        <clip>
          <near>0.1</near>
          <far>100</far>
         </clip>
        <noise>
          <type>gaussian</type>
          <mean>0.0</mean>
           <stddev>0.05</stddev>
        </noise>
      </camera>
      <always_on>1</always_on>
       <update_rate>90</update_rate>
      <visualize>0</visualize>
    </sensor>
     <sensor name="d435ired2" type="camera">
      <camera name="d435">
         <horizontal_fov>1.4870205226991688</horizontal_fov>
        <image>
           <width>1280</width>
          <height>720</height>
          <format>L_INT8</format>
         </image>
        <clip>
          <near>0.1</near>
          <far>100</far>
         </clip>
        <noise>
          <type>gaussian</type>
          <mean>0.0</mean>
           <stddev>0.05</stddev>
        </noise>
      </camera>
      <always_on>1</always_on>
       <update_rate>90</update_rate>
      <visualize>0</visualize>
    </sensor>
     <sensor name="d435depth" type="depth">
      <camera name="d435">
         <horizontal_fov>1.4870205226991688</horizontal_fov>
        <image>
           <width>1280</width>
          <height>720</height>
        </image>
         <clip>
          <near>0.1</near>
          <far>100</far>
        </clip>
         <noise>
          <type>gaussian</type>
          <mean>0.0</mean>
           <stddev>0.100</stddev>
        </noise>
      </camera>
      <always_on>1</always_on>
       <update_rate>90</update_rate>
      <visualize>0</visualize>
    </sensor>
   </gazebo>
  <gazebo>
    <plugin filename="librealsense_gazebo_plugin.so"  name="camera">
      <prefix>d435</prefix>
      <depthUpdateRate>60.0</depthUpdateRate>
       <colorUpdateRate>60.0</colorUpdateRate>
      <infraredUpdateRate>60.0</infraredUpdateRate>
       <depthTopicName>depth/image_raw</depthTopicName>
      <depthCameraInfoTopicName>depth/camera_info</depthCameraInfoTopicName>
       <colorTopicName>color/image_raw</colorTopicName>
      <colorCameraInfoTopicName>color/camera_info</colorCameraInfoTopicName>
       <infrared1TopicName>infra1/image_raw</infrared1TopicName>
      <infrared1CameraInfoTopicName>infra1/camera_info</infrared1CameraInfoTopicName>
       <infrared2TopicName>infra2/image_raw</infrared2TopicName>
      <infrared2CameraInfoTopicName>infra2/camera_info</infrared2CameraInfoTopicName>
       <colorOpticalframeName>camera_color_optical_frame</colorOpticalframeName>
       <depthOpticalframeName>camera_depth_optical_frame</depthOpticalframeName>
       <infrared1OpticalframeName>camera_infrared1_optical_frame</infrared1OpticalframeName>
       <infrared2OpticalframeName>camera_infrared2_optical_frame</infrared2OpticalframeName>
       <rangeMinDepth>0.2</rangeMinDepth>
      <rangeMaxDepth>10.0</rangeMaxDepth>
       <pointCloud>true</pointCloud>
      <pointCloudTopicName>depth/points</pointCloudTopicName>
       <pointCloudCutoff>0.5</pointCloudCutoff>
    </plugin>
  </gazebo>
  <gazebo  reference="panda2_joint1">
    <!-- Needed for ODE to output external wrenches  on joints -->
    <provideFeedback>true</provideFeedback>
  </gazebo>
  <transmission  name="panda2_joint1_transmission">
    <type>transmission_interface/SimpleTransmission</type>
     <joint name="panda2_joint1">
      <hardwareInterface>hardware_interface/PositionJointInterface</hardwareInterface>
     </joint>
    <actuator name="panda2_joint1_motor">
      <hardwareInterface>hardware_interface/PositionJointInterface</hardwareInterface>
     </actuator>
  </transmission>
  <gazebo reference="panda2_joint2">
     <!-- Needed for ODE to output external wrenches on joints -->
    <provideFeedback>true</provideFeedback>
   </gazebo>
  <transmission name="panda2_joint2_transmission">
    <type>transmission_interface/SimpleTransmission</type>
     <joint name="panda2_joint2">
      <hardwareInterface>hardware_interface/PositionJointInterface</hardwareInterface>
     </joint>
    <actuator name="panda2_joint2_motor">
      <hardwareInterface>hardware_interface/PositionJointInterface</hardwareInterface>
     </actuator>
  </transmission>
  <gazebo reference="panda2_joint3">
     <!-- Needed for ODE to output external wrenches on joints -->
    <provideFeedback>true</provideFeedback>
   </gazebo>
  <transmission name="panda2_joint3_transmission">
    <type>transmission_interface/SimpleTransmission</type>
     <joint name="panda2_joint3">
      <hardwareInterface>hardware_interface/PositionJointInterface</hardwareInterface>
     </joint>
    <actuator name="panda2_joint3_motor">
      <hardwareInterface>hardware_interface/PositionJointInterface</hardwareInterface>
     </actuator>
  </transmission>
  <gazebo reference="panda2_joint4">
     <!-- Needed for ODE to output external wrenches on joints -->
    <provideFeedback>true</provideFeedback>
   </gazebo>
  <transmission name="panda2_joint4_transmission">
    <type>transmission_interface/SimpleTransmission</type>
     <joint name="panda2_joint4">
      <hardwareInterface>hardware_interface/PositionJointInterface</hardwareInterface>
     </joint>
    <actuator name="panda2_joint4_motor">
      <hardwareInterface>hardware_interface/PositionJointInterface</hardwareInterface>
     </actuator>
  </transmission>
  <gazebo reference="panda2_joint5">
     <!-- Needed for ODE to output external wrenches on joints -->
    <provideFeedback>true</provideFeedback>
   </gazebo>
  <transmission name="panda2_joint5_transmission">
    <type>transmission_interface/SimpleTransmission</type>
     <joint name="panda2_joint5">
      <hardwareInterface>hardware_interface/PositionJointInterface</hardwareInterface>
     </joint>
    <actuator name="panda2_joint5_motor">
      <hardwareInterface>hardware_interface/PositionJointInterface</hardwareInterface>
     </actuator>
  </transmission>
  <gazebo reference="panda2_joint6">
     <!-- Needed for ODE to output external wrenches on joints -->
    <provideFeedback>true</provideFeedback>
   </gazebo>
  <transmission name="panda2_joint6_transmission">
    <type>transmission_interface/SimpleTransmission</type>
     <joint name="panda2_joint6">
      <hardwareInterface>hardware_interface/PositionJointInterface</hardwareInterface>
     </joint>
    <actuator name="panda2_joint6_motor">
      <hardwareInterface>hardware_interface/PositionJointInterface</hardwareInterface>
     </actuator>
  </transmission>
  <gazebo reference="panda2_joint7">
     <!-- Needed for ODE to output external wrenches on joints -->
    <provideFeedback>true</provideFeedback>
   </gazebo>
  <transmission name="panda2_joint7_transmission">
    <type>transmission_interface/SimpleTransmission</type>
     <joint name="panda2_joint7">
      <hardwareInterface>hardware_interface/PositionJointInterface</hardwareInterface>
     </joint>
    <actuator name="panda2_joint7_motor">
      <hardwareInterface>hardware_interface/PositionJointInterface</hardwareInterface>
     </actuator>
  </transmission>
  <gazebo reference="panda2_joint1">
     <!-- Needed for ODE to output external wrenches on joints -->
    <provideFeedback>true</provideFeedback>
   </gazebo>
  <transmission name="panda2_joint1_transmission">
    <type>transmission_interface/SimpleTransmission</type>
     <joint name="panda2_joint1">
      <hardwareInterface>hardware_interface/VelocityJointInterface</hardwareInterface>
     </joint>
    <actuator name="panda2_joint1_motor">
      <hardwareInterface>hardware_interface/VelocityJointInterface</hardwareInterface>
     </actuator>
  </transmission>
  <gazebo reference="panda2_joint2">
     <!-- Needed for ODE to output external wrenches on joints -->
    <provideFeedback>true</provideFeedback>
   </gazebo>
  <transmission name="panda2_joint2_transmission">
    <type>transmission_interface/SimpleTransmission</type>
     <joint name="panda2_joint2">
      <hardwareInterface>hardware_interface/VelocityJointInterface</hardwareInterface>
     </joint>
    <actuator name="panda2_joint2_motor">
      <hardwareInterface>hardware_interface/VelocityJointInterface</hardwareInterface>
     </actuator>
  </transmission>
  <gazebo reference="panda2_joint3">
     <!-- Needed for ODE to output external wrenches on joints -->
    <provideFeedback>true</provideFeedback>
   </gazebo>
  <transmission name="panda2_joint3_transmission">
    <type>transmission_interface/SimpleTransmission</type>
     <joint name="panda2_joint3">
      <hardwareInterface>hardware_interface/VelocityJointInterface</hardwareInterface>
     </joint>
    <actuator name="panda2_joint3_motor">
      <hardwareInterface>hardware_interface/VelocityJointInterface</hardwareInterface>
     </actuator>
  </transmission>
  <gazebo reference="panda2_joint4">
     <!-- Needed for ODE to output external wrenches on joints -->
    <provideFeedback>true</provideFeedback>
   </gazebo>
  <transmission name="panda2_joint4_transmission">
    <type>transmission_interface/SimpleTransmission</type>
     <joint name="panda2_joint4">
      <hardwareInterface>hardware_interface/VelocityJointInterface</hardwareInterface>
     </joint>
    <actuator name="panda2_joint4_motor">
      <hardwareInterface>hardware_interface/VelocityJointInterface</hardwareInterface>
     </actuator>
  </transmission>
  <gazebo reference="panda2_joint5">
     <!-- Needed for ODE to output external wrenches on joints -->
    <provideFeedback>true</provideFeedback>
   </gazebo>
  <transmission name="panda2_joint5_transmission">
    <type>transmission_interface/SimpleTransmission</type>
     <joint name="panda2_joint5">
      <hardwareInterface>hardware_interface/VelocityJointInterface</hardwareInterface>
     </joint>
    <actuator name="panda2_joint5_motor">
      <hardwareInterface>hardware_interface/VelocityJointInterface</hardwareInterface>
     </actuator>
  </transmission>
  <gazebo reference="panda2_joint6">
     <!-- Needed for ODE to output external wrenches on joints -->
    <provideFeedback>true</provideFeedback>
   </gazebo>
  <transmission name="panda2_joint6_transmission">
    <type>transmission_interface/SimpleTransmission</type>
     <joint name="panda2_joint6">
      <hardwareInterface>hardware_interface/VelocityJointInterface</hardwareInterface>
     </joint>
    <actuator name="panda2_joint6_motor">
      <hardwareInterface>hardware_interface/VelocityJointInterface</hardwareInterface>
     </actuator>
  </transmission>
  <gazebo reference="panda2_joint7">
     <!-- Needed for ODE to output external wrenches on joints -->
    <provideFeedback>true</provideFeedback>
   </gazebo>
  <transmission name="panda2_joint7_transmission">
    <type>transmission_interface/SimpleTransmission</type>
     <joint name="panda2_joint7">
      <hardwareInterface>hardware_interface/VelocityJointInterface</hardwareInterface>
     </joint>
    <actuator name="panda2_joint7_motor">
      <hardwareInterface>hardware_interface/VelocityJointInterface</hardwareInterface>
     </actuator>
  </transmission>
  <gazebo reference="panda2_joint1">
     <!-- Needed for ODE to output external wrenches on joints -->
    <provideFeedback>true</provideFeedback>
   </gazebo>
  <transmission name="panda2_joint1_transmission">
    <type>transmission_interface/SimpleTransmission</type>
     <joint name="panda2_joint1">
      <hardwareInterface>hardware_interface/EffortJointInterface</hardwareInterface>
     </joint>
    <actuator name="panda2_joint1_motor">
      <hardwareInterface>hardware_interface/EffortJointInterface</hardwareInterface>
     </actuator>
  </transmission>
  <gazebo reference="panda2_joint2">
     <!-- Needed for ODE to output external wrenches on joints -->
    <provideFeedback>true</provideFeedback>
   </gazebo>
  <transmission name="panda2_joint2_transmission">
    <type>transmission_interface/SimpleTransmission</type>
     <joint name="panda2_joint2">
      <hardwareInterface>hardware_interface/EffortJointInterface</hardwareInterface>
     </joint>
    <actuator name="panda2_joint2_motor">
      <hardwareInterface>hardware_interface/EffortJointInterface</hardwareInterface>
     </actuator>
  </transmission>
  <gazebo reference="panda2_joint3">
     <!-- Needed for ODE to output external wrenches on joints -->
    <provideFeedback>true</provideFeedback>
   </gazebo>
  <transmission name="panda2_joint3_transmission">
    <type>transmission_interface/SimpleTransmission</type>
     <joint name="panda2_joint3">
      <hardwareInterface>hardware_interface/EffortJointInterface</hardwareInterface>
     </joint>
    <actuator name="panda2_joint3_motor">
      <hardwareInterface>hardware_interface/EffortJointInterface</hardwareInterface>
     </actuator>
  </transmission>
  <gazebo reference="panda2_joint4">
     <!-- Needed for ODE to output external wrenches on joints -->
    <provideFeedback>true</provideFeedback>
   </gazebo>
  <transmission name="panda2_joint4_transmission">
    <type>transmission_interface/SimpleTransmission</type>
     <joint name="panda2_joint4">
      <hardwareInterface>hardware_interface/EffortJointInterface</hardwareInterface>
     </joint>
    <actuator name="panda2_joint4_motor">
      <hardwareInterface>hardware_interface/EffortJointInterface</hardwareInterface>
     </actuator>
  </transmission>
  <gazebo reference="panda2_joint5">
     <!-- Needed for ODE to output external wrenches on joints -->
    <provideFeedback>true</provideFeedback>
   </gazebo>
  <transmission name="panda2_joint5_transmission">
    <type>transmission_interface/SimpleTransmission</type>
     <joint name="panda2_joint5">
      <hardwareInterface>hardware_interface/EffortJointInterface</hardwareInterface>
     </joint>
    <actuator name="panda2_joint5_motor">
      <hardwareInterface>hardware_interface/EffortJointInterface</hardwareInterface>
     </actuator>
  </transmission>
  <gazebo reference="panda2_joint6">
     <!-- Needed for ODE to output external wrenches on joints -->
    <provideFeedback>true</provideFeedback>
   </gazebo>
  <transmission name="panda2_joint6_transmission">
    <type>transmission_interface/SimpleTransmission</type>
     <joint name="panda2_joint6">
      <hardwareInterface>hardware_interface/EffortJointInterface</hardwareInterface>
     </joint>
    <actuator name="panda2_joint6_motor">
      <hardwareInterface>hardware_interface/EffortJointInterface</hardwareInterface>
     </actuator>
  </transmission>
  <gazebo reference="panda2_joint7">
     <!-- Needed for ODE to output external wrenches on joints -->
    <provideFeedback>true</provideFeedback>
   </gazebo>
  <transmission name="panda2_joint7_transmission">
    <type>transmission_interface/SimpleTransmission</type>
     <joint name="panda2_joint7">
      <hardwareInterface>hardware_interface/EffortJointInterface</hardwareInterface>
     </joint>
    <actuator name="panda2_joint7_motor">
      <hardwareInterface>hardware_interface/EffortJointInterface</hardwareInterface>
     </actuator>
  </transmission>
  <transmission name="panda2_franka_state"  >
    <type>franka_hw/FrankaStateInterface</type>
    <joint name="panda2_joint1"  >
      <hardwareInterface>franka_hw/FrankaStateInterface</hardwareInterface>
     </joint>
    <joint name="panda2_joint2">
      <hardwareInterface>franka_hw/FrankaStateInterface</hardwareInterface>
     </joint>
    <joint name="panda2_joint3">
      <hardwareInterface>franka_hw/FrankaStateInterface</hardwareInterface>
     </joint>
    <joint name="panda2_joint4">
      <hardwareInterface>franka_hw/FrankaStateInterface</hardwareInterface>
     </joint>
    <joint name="panda2_joint5">
      <hardwareInterface>franka_hw/FrankaStateInterface</hardwareInterface>
     </joint>
    <joint name="panda2_joint6">
      <hardwareInterface>franka_hw/FrankaStateInterface</hardwareInterface>
     </joint>
    <joint name="panda2_joint7">
      <hardwareInterface>franka_hw/FrankaStateInterface</hardwareInterface>
     </joint>
    <actuator name="panda2_motor1">
      <hardwareInterface>franka_hw/FrankaStateInterface</hardwareInterface>
     </actuator>
    <actuator name="panda2_motor2">
      <hardwareInterface>franka_hw/FrankaStateInterface</hardwareInterface>
     </actuator>
    <actuator name="panda2_motor3">
      <hardwareInterface>franka_hw/FrankaStateInterface</hardwareInterface>
     </actuator>
    <actuator name="panda2_motor4">
      <hardwareInterface>franka_hw/FrankaStateInterface</hardwareInterface>
     </actuator>
    <actuator name="panda2_motor5">
      <hardwareInterface>franka_hw/FrankaStateInterface</hardwareInterface>
     </actuator>
    <actuator name="panda2_motor6">
      <hardwareInterface>franka_hw/FrankaStateInterface</hardwareInterface>
     </actuator>
    <actuator name="panda2_motor7">
      <hardwareInterface>franka_hw/FrankaStateInterface</hardwareInterface>
     </actuator>
  </transmission>
  <transmission name="panda2_franka_model"  >
    <type>franka_hw/FrankaModelInterface</type>
    <joint name="panda2_joint1"  >
      <role>root</role>
      <hardwareInterface>franka_hw/FrankaModelInterface</hardwareInterface>
     </joint>
    <joint name="panda2_joint8">
      <role>tip</role>
       <hardwareInterface>franka_hw/FrankaModelInterface</hardwareInterface>
    </joint>
     <actuator name="panda2_joint1_motor_root">
      <hardwareInterface>franka_hw/FrankaModelInterface</hardwareInterface>
     </actuator>
    <actuator name="panda2_joint8_motor_tip">
      <hardwareInterface>franka_hw/FrankaModelInterface</hardwareInterface>
     </actuator>
  </transmission>
  <gazebo reference="panda2_finger_joint1"  >
    <!-- Needed for ODE to output external wrenches on joints -->
    <provideFeedback>true</provideFeedback>
   </gazebo>
  <transmission name="panda2_finger_joint1_transmission">
    <type>transmission_interface/SimpleTransmission</type>
     <joint name="panda2_finger_joint1">
      <hardwareInterface>hardware_interface/EffortJointInterface</hardwareInterface>
     </joint>
    <actuator name="panda2_finger_joint1_motor">
      <hardwareInterface>hardware_interface/EffortJointInterface</hardwareInterface>
     </actuator>
  </transmission>
  <gazebo reference="panda2_finger_joint2"  >
    <!-- Needed for ODE to output external wrenches on joints -->
    <provideFeedback>true</provideFeedback>
   </gazebo>
  <transmission name="panda2_finger_joint2_transmission">
    <type>transmission_interface/SimpleTransmission</type>
     <joint name="panda2_finger_joint2">
      <hardwareInterface>hardware_interface/EffortJointInterface</hardwareInterface>
     </joint>
    <actuator name="panda2_finger_joint2_motor">
      <hardwareInterface>hardware_interface/EffortJointInterface</hardwareInterface>
     </actuator>
  </transmission>
  <gazebo reference="panda2_leftfinger">
     <collision>
      <max_contacts>10</max_contacts>
      <surface>
         <contact>
          <ode>
            <!-- These two parameter need application  specific tuning. -->
            <!-- Usually you want no "snap out" velocity  and a generous -->
            <!-- penetration depth to keep the grasping stable  -->
            <max_vel>0</max_vel>
            <min_depth>0.001</min_depth>
           </ode>
        </contact>
        <friction>
          <ode>
             <mu>1.13</mu>
            <mu2>1.13</mu2>
          </ode>
         </friction>
        <bounce/>
      </surface>
    </collision>
  </gazebo>
   <gazebo reference="panda2_rightfinger">
    <collision>
      <max_contacts>10</max_contacts>
       <surface>
        <contact>
          <ode>
            <!-- These two  parameter need application specific tuning. -->
            <!-- Usually you  want no "snap out" velocity and a generous -->
            <!-- penetration  depth to keep the grasping stable -->
            <max_vel>0</max_vel>
             <min_depth>0.001</min_depth>
          </ode>
        </contact>
         <friction>
          <ode>
            <mu>1.13</mu>
            <mu2>1.13</mu2>
           </ode>
        </friction>
        <bounce/>
      </surface>
     </collision>
  </gazebo>
  <gazebo>
    <plugin filename="libgazebo_ros_control.so"  name="gazebo_ros_control">
      <controlPeriod>0.001</controlPeriod>
       <robotSimType>franka_gazebo/FrankaHWSim</robotSimType>
    </plugin>
    <self_collide>true</self_collide>
   </gazebo>
  <!-- wall behind the table -->
</robot>
